<?xml version="1.0" ?>
<!-- =================================================================================== -->
<!-- |    This document was autogenerated by xacro from demo05_car_base.urdf.xacro     | -->
<!-- |    EDITING THIS FILE BY HAND IS NOT RECOMMENDED                                 | -->
<!-- =================================================================================== -->
<robot name="mycar">
  <!-- 1.添加一个尺寸极小的link -->
  <link name="base_footprint">
    <visual>
      <geometry>
        <sphere radius="0.001"/>
      </geometry>
    </visual>
  </link>
  <link name="base_link">
    <visual>
      <geometry>
        <cylinder length="0.08" radius="0.1"/>
      </geometry>
      <origin rpy="0 0 0" xyz="0 0 0"/>
      <material name="baselink_color">
        <color rgba="0.8 0.3 0.1 0.5"/>
      </material>
    </visual>
  </link>
  <!-- 2.2joint -->
  <joint name="link2footprint" type="fixed">
    <parent link="base_footprint"/>
    <child link="base_link"/>
    <!-- 关节z上的设置等于车体高度/2+离地间距 -->
    <!-- link的偏移是物体中心与大地坐标系原点的偏移，joint的偏移量是两个link坐标系之间的偏移 -->
    <origin rpy="0 0 0" xyz="0 0 0.055"/>
  </joint>
  <link name="left_wheel">
    <visual>
      <geometry>
        <cylinder length="0.015" radius="0.0325"/>
      </geometry>
      <origin rpy="1.57079635 0 0" xyz="0 0 0"/>
      <material name="wheel_color">
        <color rgba="0.8 0.3 0.1 0.5"/>
      </material>
    </visual>
  </link>
  <!-- 3.2joint -->
  <joint name="left2link" type="continuous">
    <parent link="base_link"/>
    <child link="left_wheel"/>
    <!-- 这里的偏移是父子级之间的位置关系，不是参考的大地，参考父级坐标，判断大小和正负 -->
    <origin rpy="0 0 0" xyz="0 0.1 -0.0225"/>
    <!-- 参考Axes,所以是绕y轴旋转 -->
    <axis xyz="0 1 0"/>
  </joint>
  <link name="right_wheel">
    <visual>
      <geometry>
        <cylinder length="0.015" radius="0.0325"/>
      </geometry>
      <origin rpy="1.57079635 0 0" xyz="0 0 0"/>
      <material name="wheel_color">
        <color rgba="0.8 0.3 0.1 0.5"/>
      </material>
    </visual>
  </link>
  <!-- 3.2joint -->
  <joint name="right2link" type="continuous">
    <parent link="base_link"/>
    <child link="right_wheel"/>
    <!-- 这里的偏移是父子级之间的位置关系，不是参考的大地，参考父级坐标，判断大小和正负 -->
    <origin rpy="0 0 0" xyz="0 -0.1 -0.0225"/>
    <!-- 参考Axes,所以是绕y轴旋转 -->
    <axis xyz="0 1 0"/>
  </joint>
</robot>

