<!-- 需求：设置机器人底盘，并添加摄像头 -->
<robot name="mycar">
<!-- 底盘link -->
<link name="base_link">
  <visual>
   <geometry>
    <box size="0.3 0.2 0.1" />
   </geometry>
        <origin xyz="0 0.0 0.0" rpy="0 0.0 0"/>
     <material name="car_color">
      <color rgba="0.5 0.7 0.6 0.5" />
     </material>
  </visual>
 </link>
 <!-- 摄像头link -->
 <link name="camera">
  <visual>
   <geometry>
    <box size="0.02 0.05 0.05" />
   </geometry>
   <!-- 先试用默认，后期需要修改,改为0.025，使摄像头不下沉 -->
        <origin xyz="0 0.0 0.025" rpy="0 0.0 0"/>
     <material name="camera_color" >
      <color rgba="0 0 1 0.5" />
     </material>
  </visual>
 </link>
 <!-- 关节 -->
 <joint name="camera2base" type="continuous" >
 <!-- 父级link -->
 <parent link="base_link"/>
 <!-- 子级link -->
 <child link="camera"/>
 <!-- 设置关节的偏移量，关节是在子级的物理中心的 -->
 <origin xyz="0.12 0 0.05" rpy="0 0 0" />
 <!-- 设置关节旋转参考的坐标轴,绕谁转谁就是1 -->
 <axis xyz="0 0 1" />
 </joint>
</robot>